Workbook

Sheet Decrementos Múltiples
B2: Hombres, 2019
B3: Age x | C3: n | D3: nDx | E3: nDxi | I3: nqx | K3: e0 | M3: nqx_i | O3: ndx_i | Q3: L | R3: T | S3: e0_i | T3: diff
B4: 0 | C4: 1 | D4: ='Defunciones generales'!D21 -> 644.43531 | E4: =Homicidios!D543 -> 2 | F4: =(D4-E4)/D4 -> 0.99689651 | G4: =LT!H40 -> 100000 | H4: =1-LT!G40 -> 0.986054 | I4: =1-H4 -> 0.013946 | J4: =LT!E2 -> 0.09 | K4: =LT!L40 -> 72.41 | L4: =H4^F4 -> 0.98609698 | M4: =1-L4 -> 0.013903021 | N4: 100000 | O4: =N4*M4 -> 1390.3021 | P4: =C4+(F4*(I4/M4)*(J4-C4)) -> 0.090019785 | Q4: =(C4*N5)+(P4*O4) -> 98734.853 | R4: =R5+Q4 -> 7329607.4 | S4: =R4/N4 -> 73.296074 | T4: =S4-K4 -> 0.8860738
B5: 1 | C5: 4 | D5: ='Defunciones generales'!D22 -> 125.08657 | E5: =Homicidios!D544 -> 3 | F5: =(D5-E5)/D5 -> 0.97601661 | G5: =LT!H41 -> 99997.5 | H5: =1-LT!G41 -> 0.997596 | I5: =1-H5 -> 0.002404 | J5: =LT!E3 -> 1.61 | K5: =LT!L41 -> 71.01 | L5: =H5^F5 -> 0.99765359 | M5: =1-L5 -> 0.0023464116 | N5: =N4*L4 -> 98609.698 | O5: =N5*M5 -> 231.37894 | P5: =C5+(F5*(I5/M5)*(J5-C5)) -> 1.610069 | Q5: =(C5*N6)+(P5*O5) -> 393885.81 | R5: =R6+Q5 -> 7230872.5 | S5: =R5/N5 -> 73.328209 | T5: =S5-K5 -> 2.3182089
B6: 5 | C6: 5 | D6: ='Defunciones generales'!D23 -> 82.056789 | E6: =Homicidios!D545 -> 7 | F6: =(D6-E6)/D6 -> 0.91469323 | G6: =LT!H42 -> 99993 | H6: =1-LT!G42 -> 0.998766 | I6: =1-H6 -> 0.001234 | J6: =LT!E4 -> 2.5 | K6: =LT!L42 -> 67.54 | L6: =H6^F6 -> 0.99887121 | M6: =1-L6 -> 0.0011287909 | N6: =N5*L5 -> 98378.319 | O6: =N6*M6 -> 111.04855 | P6: =C6+(F6*(I6/M6)*(J6-C6)) -> 2.5001316 | Q6: =(C6*N7)+(P6*O6) -> 491613.99 | R6: =R7+Q6 -> 6836986.7 | S6: =R6/N6 -> 69.496885 | T6: =S6-K6 -> 1.956885
B7: 10 | C7: 5 | D7: ='Defunciones generales'!D24 -> 132.09142 | E7: =Homicidios!D546 -> 24 | F7: =(D7-E7)/D7 -> 0.81830765 | G7: =LT!H43 -> 99988.001 | H7: =1-LT!G43 -> 0.998315 | I7: =1-H7 -> 0.001685 | J7: =LT!E5 -> 2.5 | K7: =LT!L43 -> 61.38 | L7: =H7^F7 -> 0.99862094 | M7: =1-L7 -> 0.0013790596 | N7: =N6*L6 -> 98267.27 | O7: =N7*M7 -> 135.51642 | P7: =(((-5/24)*O6)+((2.5)*O7)+((5/24)*O8))/O7 -> 2.8017032 | Q7: =(C7*N8)+(P7*O7) -> 491038.45 | R7: =R8+Q7 -> 6345372.7 | S7: =R7/N7 -> 64.572596 | T7: =S7-K7 -> 3.1925957
B8: 15 | C8: 5 | D8: ='Defunciones generales'!D25 -> 572.39614 | E8: =Homicidios!D547 -> 281 | F8: =(D8-E8)/D8 -> 0.50908125 | G8: =LT!H44 -> 99968.005 | H8: =1-LT!G44 -> 0.993858 | I8: =1-H8 -> 0.006142 | J8: =LT!E6 -> 2.5 | K8: =LT!L44 -> 59.35 | L8: =H8^F8 -> 0.99686849 | M8: =1-L8 -> 0.0031315054 | N8: =N7*L7 -> 98131.754 | O8: =N8*M8 -> 307.30012 | P8: =(((-5/24)*O7)+((2.5)*O8)+((5/24)*O9))/O8 -> 2.7473894 | Q8: =(C8*N9)+(P8*O8) -> 489966.54 | R8: =R9+Q8 -> 5854334.3 | S8: =R8/N8 -> 59.657899 | T8: =S8-K8 -> 0.30789912
B9: 20 | C9: 5 | D9: ='Defunciones generales'!D26 -> 1019.7057 | E9: =Homicidios!D548 -> 568 | F9: =(D9-E9)/D9 -> 0.44297654 | G9: =LT!H45 -> 99704.438 | H9: =1-LT!G45 -> 0.988489 | I9: =1-H9 -> 0.011511 | J9: =LT!E7 -> 2.5 | K9: =LT!L45 -> 54.71 | L9: =H9^F9 -> 0.99488445 | M9: =1-L9 -> 0.0051155488 | N9: =N8*L8 -> 97824.454 | O9: =N9*M9 -> 500.42577 | P9: =(((-5/24)*O8)+((2.5)*O9)+((5/24)*O10))/O9 -> 2.623782 | Q9: =(C9*N10)+(P9*O9) -> 487933.15 | R9: =R10+Q9 -> 5364367.7 | S9: =R9/N9 -> 54.836675 | T9: =S9-K9 -> 0.12667453
B10: 25 | C10: 5 | D10: ='Defunciones generales'!D27 -> 1105.7653 | E10: =Homicidios!D549 -> 632 | F10: =(D10-E10)/D10 -> 0.42845013 | G10: =LT!H46 -> 99174.923 | H10: =1-LT!G46 -> 0.98556 | I10: =1-H10 -> 0.01444 | J10: =LT!E8 -> 2.5 | K10: =LT!L46 -> 49.68 | L10: =H10^F10 -> 0.99378745 | M10: =1-L10 -> 0.0062125452 | N10: =N9*L9 -> 97324.028 | O10: =N10*M10 -> 604.62993 | P10: =(((-5/24)*O9)+((2.5)*O10)+((5/24)*O11))/O10 -> 2.5698014 | Q10: =(C10*N11)+(P10*O10) -> 485150.77 | R10: =R11+Q10 -> 4876434.6 | S10: =R10/N10 -> 50.105146 | T10: =S10-K10 -> 0.42514551
B11: 30 | C11: 5 | D11: ='Defunciones generales'!D28 -> 1028.7119 | E11: =Homicidios!D550 -> 548 | F11: =(D11-E11)/D11 -> 0.467295 | G11: =LT!H47 -> 98593.978 | H11: =1-LT!G47 -> 0.98451 | I11: =1-H11 -> 0.01549 | J11: =LT!E9 -> 2.5 | K11: =LT!L47 -> 45.09 | L11: =H11^F11 -> 0.9927315 | M11: =1-L11 -> 0.0072685024 | N11: =N10*L10 -> 96719.398 | O11: =N11*M11 -> 703.00517 | P11: =(((-5/24)*O10)+((2.5)*O11)+((5/24)*O12))/O11 -> 2.6030385 | Q11: =(C11*N12)+(P11*O11) -> 481911.91 | R11: =R12+Q11 -> 4391283.8 | S11: =R11/N11 -> 45.402307 | T11: =S11-K11 -> 0.31230711
B12: 35 | C12: 5 | D12: ='Defunciones generales'!D29 -> 964.66762 | E12: =Homicidios!D551 -> 425 | F12: =(D12-E12)/D12 -> 0.55943375 | G12: =LT!H48 -> 98089.977 | H12: =1-LT!G48 -> 0.98234 | I12: =1-H12 -> 0.01766 | J12: =LT!E10 -> 2.5 | K12: =LT!L48 -> 40.28 | L12: =H12^F12 -> 0.99008164 | M12: =1-L12 -> 0.0099183631 | N12: =N11*L11 -> 96016.393 | O12: =N12*M12 -> 952.32545 | P12: =(((-5/24)*O11)+((2.5)*O12)+((5/24)*O13))/O12 -> 2.6706896 | Q12: =(C12*N13)+(P12*O12) -> 477863.7 | R12: =R13+Q12 -> 3909371.9 | S12: =R12/N12 -> 40.715671 | T12: =S12-K12 -> 0.43567139
B13: 40 | C13: 5 | D13: ='Defunciones generales'!D30 -> 1056.7313 | E13: =Homicidios!D552 -> 315 | F13: =(D13-E13)/D13 -> 0.70191099 | G13: =LT!H49 -> 97692.539 | H13: =1-LT!G49 -> 0.977845 | I13: =1-H13 -> 0.022155 | J13: =LT!E11 -> 2.5 | K13: =LT!L49 -> 36.09 | L13: =H13^F13 -> 0.98439731 | M13: =1-L13 -> 0.015602687 | N13: =N12*L12 -> 95064.068 | O13: =N13*M13 -> 1483.2549 | P13: =(((-5/24)*O12)+((2.5)*O13)+((5/24)*O14))/O13 -> 2.661548 | Q13: =(C13*N14)+(P13*O13) -> 471851.82 | R13: =R14+Q13 -> 3431508.2 | S13: =R13/N13 -> 36.096795 | T13: =S13-K13 -> 0.0067954587
B14: 45 | C14: 5 | D14: ='Defunciones generales'!D31 -> 1103.7639 | E14: =Homicidios!D553 -> 220 | F14: =(D14-E14)/D14 -> 0.80068201 | G14: =LT!H50 -> 97391.622 | H14: =1-LT!G50 -> 0.972019 | I14: =1-H14 -> 0.027981 | J14: =LT!E12 -> 2.5 | K14: =LT!L50 -> 31.6 | L14: =H14^F14 -> 0.97753293 | M14: =1-L14 -> 0.022467068 | N14: =N13*L13 -> 93580.813 | O14: =N14*M14 -> 2102.4864 | P14: =(((-5/24)*O13)+((2.5)*O14)+((5/24)*O15))/O14 -> 2.6511749 | Q14: =(C14*N15)+(P14*O14) -> 462965.69 | R14: =R15+Q14 -> 2959656.4 | S14: =R14/N14 -> 31.626744 | T14: =S14-K14 -> 0.026743766
B15: 50 | C15: 5 | D15: ='Defunciones generales'!D32 -> 1150.7964 | E15: =Homicidios!D554 -> 131 | F15: =(D15-E15)/D15 -> 0.88616579 | G15: =LT!H51 -> 97186.828 | H15: =1-LT!G51 -> 0.962962 | I15: =1-H15 -> 0.037038 | J15: =LT!E13 -> 2.5 | K15: =LT!L51 -> 26.55 | L15: =H15^F15 -> 0.96710803 | M15: =1-L15 -> 0.032891971 | N15: =N14*L14 -> 91478.326 | O15: =N15*M15 -> 3008.9024 | P15: =(((-5/24)*O14)+((2.5)*O15)+((5/24)*O16))/O15 -> 2.6730688 | Q15: =(C15*N16)+(P15*O15) -> 450390.12 | R15: =R16+Q15 -> 2496690.7 | S15: =R15/N15 -> 27.292702 | T15: =S15-K15 -> 0.74270196
B16: 55 | C16: 5 | D16: ='Defunciones generales'!D33 -> 1344.9308 | E16: =Homicidios!D555 -> 62 | F16: =(D16-E16)/D16 -> 0.95390097 | G16: =LT!H52 -> 97059.111 | H16: =1-LT!G52 -> 0.945537 | I16: =1-H16 -> 0.054463 | J16: =LT!E14 -> 2.5 | K16: =LT!L52 -> 22.98 | L16: =H16^F16 -> 0.9479812 | M16: =1-L16 -> 0.052018801 | N16: =N15*L15 -> 88469.424 | O16: =N16*M16 -> 4602.0734 | P16: =(((-5/24)*O15)+((2.5)*O16)+((5/24)*O17))/O16 -> 2.6347267 | Q16: =(C16*N17)+(P16*O16) -> 431461.96 | R16: =R17+Q16 -> 2046300.6 | S16: =R16/N16 -> 23.130032 | T16: =S16-K16 -> 0.15003163
B17: 60 | C17: 5 | D17: ='Defunciones generales'!D34 -> 1419.9827 | E17: =Homicidios!D556 -> 42 | F17: =(D17-E17)/D17 -> 0.97042218 | G17: =LT!H53 -> 97003.803 | H17: =1-LT!G53 -> 0.926544 | I17: =1-H17 -> 0.073456 | J17: =LT!E15 -> 2.5 | K17: =LT!L53 -> 18.63 | L17: =H17^F17 -> 0.9286372 | M17: =1-L17 -> 0.071362797 | N17: =N16*L16 -> 83867.35 | O17: =N17*M17 -> 5985.0087 | P17: =(((-5/24)*O16)+((2.5)*O17)+((5/24)*O18))/O17 -> 2.6092343 | Q17: =(C17*N18)+(P17*O17) -> 405028 | R17: =R18+Q17 -> 1614838.6 | S17: =R17/N17 -> 19.254675 | T17: =S17-K17 -> 0.62467545
B18: 65 | C18: 5 | D18: ='Defunciones generales'!D35 -> 1542.0672 | E18: =Homicidios!D557 -> 17 | F18: =(D18-E18)/D18 -> 0.98897584 | G18: =LT!H54 -> 96963.555 | H18: =1-LT!G54 -> 0.899567 | I18: =1-H18 -> 0.100433 | J18: =LT!E16 -> 2.5 | K18: =LT!L54 -> 15.03 | L18: =H18^F18 -> 0.90061724 | M18: =1-L18 -> 0.099382758 | N18: =N17*L17 -> 77882.342 | O18: =N18*M18 -> 7740.1619 | P18: =(((-5/24)*O17)+((2.5)*O18)+((5/24)*O19))/O18 -> 2.6090718 | Q18: =(C18*N19)+(P18*O18) -> 370905.54 | R18: =R19+Q18 -> 1209810.6 | S18: =R18/N18 -> 15.533824 | T18: =S18-K18 -> 0.50382433
... B20: 75 | C20: 5 | D20: ='Defunciones generales'!D37 -> 1722.1919 | E20: =Homicidios!D559 -> 8 | F20: =(D20-E20)/D20 -> 0.99535476 | G20: =LT!H56 -> 96935.44 | H20: =1-LT!G56 -> 0.790817 | I20: =1-H20 -> 0.209183 | J20: =LT!E18 -> 2.5 | K20: =LT!L56 -> 8.31 | L20: =H20^F20 -> 0.79167961 | M20: =1-L20 -> 0.20832039 | N20: =N19*L19 -> 60104.853 | O20: =N20*M20 -> 12521.066 | P20: =(((-5/24)*O19)+((2.5)*O20)+((5/24)*O21))/O20 -> 2.5807557 | Q20: =(C20*N21)+(P20*O20) -> 270232.74 | R20: =R21+Q20 -> 512291.47 | S20: =R20/N20 -> 8.5232964 | T20: =S20-K20 -> 0.21329643
B21: 80 | C21: 5 | D21: ='Defunciones generales'!D38 -> 1773.2272 | E21: =Homicidios!D560 -> 4 | F21: =(D21-E21)/D21 -> 0.99774423 | G21: =LT!H57 -> 96928.17 | H21: =1-LT!G57 -> 0.686478 | I21: =1-H21 -> 0.313522 | J21: =LT!E19 -> 2.5 | K21: =LT!L57 -> 5.01 | L21: =H21^F21 -> 0.68706078 | M21: =1-L21 -> 0.31293922 | N21: =N20*L20 -> 47583.786 | O21: =N21*M21 -> 14890.833 | P21: =C21+(F21*(I21/M21)*(J21-C21)) -> 2.5009943 | Q21: =(C21*N22)+(P21*O21) -> 200706.65 | R21: =R22 +Q21 -> 242058.73 | S21: =R21/N21 -> 5.0870002 | T21: =S21-K21 -> 0.077000247
B22: 85 | C22: 5 | D22: ='Defunciones generales'!D39 -> 3166.1912 | E22: =Homicidios!D561 -> 1 | F22: =(D22-E22)/D22 -> 0.99968416 | G22: =LT!H58 -> 96924.293 | H22: =1-LT!G58 -> 0 | I22: =1-H22 -> 1 | J22: =LT!E20 -> NA | K22: =LT!L58 -> 1.04 | L22: =H22^F22 -> 0 | M22: =1-L22 -> 1 | N22: =N21*L21 -> 32692.953 | O22: =N22*M22 -> 32692.953 | P22: =K22/F22 -> 1.0403286 | Q22: =N22/LT!F58 -> 41352.078 | R22: =Q22 -> 41352.078 | S22: =R22/N22 -> 1.2648621 | T22: =S22-K22 -> 0.22486213
B24: Mujeres, 2019
B26: Age x | C26: n | D26: nDx | E26: nDxi | I26: nqx | K26: e0 | M26: nqx_i | O26: ndx_i | Q26: L | R26: T | S26: e0_i | T26: diff
B27: 0 | C27: 1 | D27: ='Defunciones generales'!D78 -> 486.01069 | E27: =Homicidios!D1198 -> 1 | F27: =(D27-E27)/D27 -> 0.99794243 | G27: =LT!H59 -> 100000 | H27: =1-LT!G59 -> 0.988794 | I27: =1-H27 -> 0.011206 | J27: =LT!E78 -> 0.08 | K27: =LT!L59 -> 78.97 | L27: =H27^F27 -> 0.98881693 | M27: =1-L27 -> 0.011183072 | N27: 100000 | O27: =N27*M27 -> 1118.3072 | P27: =C27+(F27*(I27/M27)*(J27-C27)) -> 0.080010646 | Q27: =(C27*N28)+(P27*O27) -> 98971.169 | R27: =R28+Q27 -> 7974958.4 | S27: =R27/N27 -> 79.749584 | T27: =S27-K27 -> 0.77958381 | Z27: Hombres | AA27: Mujeres
B28: 1 | C28: 4 | D28: ='Defunciones generales'!D79 -> 94 | E28: =Homicidios!D1199 -> 2 | F28: =(D28-E28)/D28 -> 0.9787234 | G28: =LT!H60 -> 99998.5 | H28: =1-LT!G60 -> 0.997906 | I28: =1-H28 -> 0.002094 | J28: =LT!E79 -> 1.5 | K28: =LT!L60 -> 78.27 | L28: =H28^F28 -> 0.99795051 | M28: =1-L28 -> 0.0020494925 | N28: =N27*L27 -> 98881.693 | O28: =N28*M28 -> 202.65729 | P28: =C28+(F28*(I28/M28)*(J28-C28)) -> 1.5000557 | Q28: =(C28*N29)+(P28*O28) -> 395020.14 | R28: =R29+Q28 -> 7875987.2 | S28: =R28/N28 -> 79.650611 | T28: =S28-K28 -> 1.3806107 | Y28: Sin homicidios | Z28: =S4 -> 73.296074 | AA28: =S27 -> 79.749584
B29: 5 | C29: 5 | D29: ='Defunciones generales'!D80 -> 62 | E29: =Homicidios!D1200 -> 2 | F29: =(D29-E29)/D29 -> 0.96774194 | G29: =LT!H61 -> 99995.5 | H29: =1-LT!G61 -> 0.998936 | I29: =1-H29 -> 0.001064 | J29: =LT!E80 -> 2.5 | K29: =LT!L61 -> 74.63 | L29: =H29^F29 -> 0.9989703 | M29: =1-L29 -> 0.0010296951 | N29: =N28*L28 -> 98679.035 | O29: =N29*M29 -> 101.60932 | P29: =C29+(F29*(I29/M29)*(J29-C29)) -> 2.5000429 | Q29: =(C29*N30)+(P29*O29) -> 493141.16 | R29: =R30+Q29 -> 7480967.1 | S29: =R29/N29 -> 75.811109 | T29: =S29-K29 -> 1.1811086 | Y29: Con homicidios | Z29: =K4 -> 72.41 | AA29: =K27 -> 78.97
B30: 10 | C30: 5 | D30: ='Defunciones generales'!D81 -> 62 | E30: =Homicidios!D1201 -> 5 | F30: =(D30-E30)/D30 -> 0.91935484 | G30: =LT!H62 -> 99993.5 | H30: =1-LT!G62 -> 0.99879 | I30: =1-H30 -> 0.00121 | J30: =LT!E81 -> 2.5 | K30: =LT!L62 -> 69.94 | L30: =H30^F30 -> 0.99888753 | M30: =1-L30 -> 0.0011124737 | N30: =N29*L29 -> 98577.426 | O30: =N30*M30 -> 109.66479 | P30: =(((-5/24)*O29)+((2.5)*O30)+((5/24)*O31))/O30 -> 2.6218667 | Q30: =(C30*N31)+(P30*O30) -> 492626.33 | R30: =R31+Q30 -> 6987825.9 | S30: =R30/N30 -> 70.886674 | T30: =S30-K30 -> 0.94667442 | Z30: =Z28-Z29 -> 0.8860738 | AA30: =AA28-AA29 -> 0.77958381
B31: 15 | C31: 5 | D31: ='Defunciones generales'!D82 -> 139 | E31: =Homicidios!D1202 -> 38 | F31: =(D31-E31)/D31 -> 0.72661871 | G31: =LT!H63 -> 99987.501 | H31: =1-LT!G63 -> 0.997684 | I31: =1-H31 -> 0.002316 | J31: =LT!E82 -> 2.5 | K31: =LT!L63 -> 64.89 | L31: =H31^F31 -> 0.99831662 | M31: =1-L31 -> 0.0016833822 | N31: =N30*L30 -> 98467.761 | O31: =N31*M31 -> 165.75888 | P31: =(((-5/24)*O30)+((2.5)*O31)+((5/24)*O32))/O31 -> 2.6197463 | Q31: =(C31*N32)+(P31*O31) -> 491944.26 | R31: =R32+Q31 -> 6495199.6 | S31: =R31/N31 -> 65.962702 | T31: =S31-K31 -> 1.0727018
B32: 20 | C32: 5 | D32: ='Defunciones generales'!D83 -> 208 | E32: =Homicidios!D1203 -> 65 | F32: =(D32-E32)/D32 -> 0.6875 | G32: =LT!H64 -> 99954.011 | H32: =1-LT!G64 -> 0.996969 | I32: =1-H32 -> 0.003031 | J32: =LT!E83 -> 2.5 | K32: =LT!L64 -> 61.01 | L32: =H32^F32 -> 0.9979152 | M32: =1-L32 -> 0.0020848007 | N32: =N31*L31 -> 98302.002 | O32: =N32*M32 -> 204.94008 | P32: =(((-5/24)*O31)+((2.5)*O32)+((5/24)*O33))/O32 -> 2.5892882 | Q32: =(C32*N33)+(P32*O32) -> 491015.96 | R32: =R33+Q32 -> 6003255.3 | S32: =R32/N32 -> 61.069512 | T32: =S32-K32 -> 0.059512005
B33: 25 | C33: 5 | D33: ='Defunciones generales'!D84 -> 264 | E33: =Homicidios!D1204 -> 79 | F33: =(D33-E33)/D33 -> 0.70075758 | G33: =LT!H65 -> 99884.567 | H33: =1-LT!G65 -> 0.996313 | I33: =1-H33 -> 0.003687 | J33: =LT!E84 -> 2.5 | K33: =LT!L65 -> 54.98 | L33: =H33^F33 -> 0.99741488 | M33: =1-L33 -> 0.0025851208 | N33: =N32*L32 -> 98097.062 | O33: =N33*M33 -> 253.59275 | P33: =(((-5/24)*O32)+((2.5)*O33)+((5/24)*O34))/O33 -> 2.6131148 | Q33: =(C33*N34)+(P33*O33) -> 489880.02 | R33: =R34+Q33 -> 5512239.4 | S33: =R33/N33 -> 56.191686 | T33: =S33-K33 -> 1.2116863
B34: 30 | C34: 5 | D34: ='Defunciones generales'!D85 -> 265 | E34: =Homicidios!D1205 -> 56 | F34: =(D34-E34)/D34 -> 0.78867925 | G34: =LT!H66 -> 99819.663 | H34: =1-LT!G66 -> 0.995562 | I34: =1-H34 -> 0.004438 | J34: =LT!E85 -> 2.5 | K34: =LT!L66 -> 51.05 | L34: =H34^F34 -> 0.9964982 | M34: =1-L34 -> 0.0035018027 | N34: =N33*L33 -> 97843.47 | O34: =N34*M34 -> 342.62853 | P34: =(((-5/24)*O33)+((2.5)*O34)+((5/24)*O35))/O34 -> 2.6515584 | Q34: =(C34*N35)+(P34*O34) -> 488412.71 | R34: =R35+Q34 -> 5022359.3 | S34: =R34/N34 -> 51.330552 | T34: =S34-K34 -> 0.28055239
B35: 35 | C35: 5 | D35: ='Defunciones generales'!D86 -> 303 | E35: =Homicidios!D1206 -> 39 | F35: =(D35-E35)/D35 -> 0.87128713 | G35: =LT!H67 -> 99768.768 | H35: =1-LT!G67 -> 0.994083 | I35: =1-H35 -> 0.005917 | J35: =LT!E86 -> 2.5 | K35: =LT!L67 -> 46.13 | L35: =H35^F35 -> 0.99484263 | M35: =1-L35 -> 0.0051573735 | N35: =N34*L34 -> 97500.841 | O35: =N35*M35 -> 502.84825 | P35: =(((-5/24)*O34)+((2.5)*O35)+((5/24)*O36))/O35 -> 2.6866856 | Q35: =(C35*N36)+(P35*O35) -> 486340.96 | R35: =R36+Q35 -> 4533946.6 | S35: =R35/N35 -> 46.501616 | T35: =S35-K35 -> 0.37161565
B36: 40 | C36: 5 | D36: ='Defunciones generales'!D87 -> 358 | E36: =Homicidios!D1207 -> 25 | F36: =(D36-E36)/D36 -> 0.9301676 | G36: =LT!H68 -> 99725.876 | H36: =1-LT!G68 -> 0.991211 | I36: =1-H36 -> 0.008789 | J36: =LT!E87 -> 2.5 | K36: =LT!L68 -> 36.99 | L36: =H36^F36 -> 0.99182224 | M36: =1-L36 -> 0.0081777597 | N36: =N35*L35 -> 96997.993 | O36: =N36*M36 -> 793.22628 | P36: =(((-5/24)*O35)+((2.5)*O36)+((5/24)*O37))/O36 -> 2.6966695 | Q36: =(C36*N37)+(P36*O36) -> 483162.9 | R36: =R37+Q36 -> 4047605.7 | S36: =R36/N36 -> 41.728757 | T36: =S36-K36 -> 4.7387571
B37: 45 | C37: 5 | D37: ='Defunciones generales'!D88 -> 499 | E37: =Homicidios!D1208 -> 18 | F37: =(D37-E37)/D37 -> 0.96392786 | G37: =LT!H69 -> 99700.45 | H37: =1-LT!G69 -> 0.986506 | I37: =1-H37 -> 0.013494 | J37: =LT!E88 -> 2.5 | K37: =LT!L69 -> 36.24 | L37: =H37^F37 -> 0.98698958 | M37: =1-L37 -> 0.013010423 | N37: =N36*L36 -> 96204.767 | O37: =N37*M37 -> 1251.6647 | P37: =(((-5/24)*O36)+((2.5)*O37)+((5/24)*O38))/O37 -> 2.6798718 | Q37: =(C37*N38)+(P37*O37) -> 478119.81 | R37: =R38+Q37 -> 3564442.8 | S37: =R37/N37 -> 37.050584 | T37: =S37-K37 -> 0.81058392
B38: 50 | C38: 5 | D38: ='Defunciones generales'!D89 -> 706 | E38: =Homicidios!D1209 -> 15 | F38: =(D38-E38)/D38 -> 0.97875354 | G38: =LT!H70 -> 99682.007 | H38: =1-LT!G70 -> 0.979841 | I38: =1-H38 -> 0.020159 | J38: =LT!E89 -> 2.5 | K38: =LT!L70 -> 31.93 | L38: =H38^F38 -> 0.98026505 | M38: =1-L38 -> 0.019734947 | N38: =N37*L37 -> 94953.102 | O38: =N38*M38 -> 1873.8945 | P38: =(((-5/24)*O37)+((2.5)*O38)+((5/24)*O39))/O38 -> 2.7004333 | Q38: =(C38*N39)+(P38*O38) -> 470456.36 | R38: =R39+Q38 -> 3086323 | S38: =R38/N38 -> 32.503656 | T38: =S38-K38 -> 0.57365609
B39: 55 | C39: 5 | D39: ='Defunciones generales'!D90 -> 892 | E39: =Homicidios!D1210 -> 11 | F39: =(D39-E39)/D39 -> 0.98766816 | G39: =LT!H71 -> 99668.052 | H39: =1-LT!G71 -> 0.966781 | I39: =1-H39 -> 0.033219 | J39: =LT!E90 -> 2.5 | K39: =LT!L71 -> 27.89 | L39: =H39^F39 -> 0.96718385 | M39: =1-L39 -> 0.032816145 | N39: =N38*L38 -> 93079.207 | O39: =N39*M39 -> 3054.5008 | P39: =(((-5/24)*O38)+((2.5)*O39)+((5/24)*O40))/O39 -> 2.666393 | Q39: =(C39*N40)+(P39*O39) -> 458268.03 | R39: =R40+Q39 -> 2615866.6 | S39: =R39/N39 -> 28.103662 | T39: =S39-K39 -> 0.21366221
B40: 60 | C40: 5 | D40: ='Defunciones generales'!D91 -> 1112 | E40: =Homicidios!D1211 -> 6 | F40: =(D40-E40)/D40 -> 0.99460432 | G40: =LT!H72 -> 99660.079 | H40: =1-LT!G72 -> 0.951832 | I40: =1-H40 -> 0.048168 | J40: =LT!E91 -> 2.5 | K40: =LT!L72 -> 23.31 | L40: =H40^F40 -> 0.95208557 | M40: =1-L40 -> 0.047914429 | N40: =N39*L39 -> 90024.707 | O40: =N40*M40 -> 4313.4824 | P40: =(((-5/24)*O39)+((2.5)*O40)+((5/24)*O41))/O40 -> 2.6454422 | Q40: =(C40*N41)+(P40*O40) -> 439967.19 | R40: =R41+Q40 -> 2157598.6 | S40: =R40/N40 -> 23.966738 | T40: =S40-K40 -> 0.65673816
B41: 65 | C41: 5 | D41: ='Defunciones generales'!D92 -> 1310 | E41: =Homicidios!D1212 -> 7 | F41: =(D41-E41)/D41 -> 0.99465649 | G41: =LT!H73 -> 99654.598 | H41: =1-LT!G73 -> 0.928863 | I41: =1-H41 -> 0.071137 | J41: =LT!E92 -> 2.5 | K41: =LT!L73 -> 19.88 | L41: =H41^F41 -> 0.92922934 | M41: =1-L41 -> 0.070770659 | N41: =N40*L40 -> 85711.224 | O41: =N41*M41 -> 6065.8398 | P41: =(((-5/24)*O40)+((2.5)*O41)+((5/24)*O42))/O41 -> 2.6414092 | Q41: =(C41*N42)+(P41*O41) -> 414249.29 | R41: =R42+Q41 -> 1717631.4 | S41: =R41/N41 -> 20.039749 | T41: =S41-K41 -> 0.15974857
B42: 70 | C42: 5 | D42: ='Defunciones generales'!D93 -> 1465 | E42: =Homicidios!D1213 -> 1 | F42: =(D42-E42)/D42 -> 0.99931741 | G42: =LT!H74 -> 99648.121 | H42: =1-LT!G74 -> 0.894078 | I42: =1-H42 -> 0.105922 | J42: =LT!E93 -> 2.5 | K42: =LT!L74 -> 16.15 | L42: =H42^F42 -> 0.89414633 | M42: =1-L42 -> 0.10585367 | N42: =N41*L41 -> 79645.384 | O42: =N42*M42 -> 8430.756 | P42: =(((-5/24)*O41)+((2.5)*O42)+((5/24)*O43))/O42 -> 2.6467013 | Q42: =(C42*N43)+(P42*O42) -> 378386.83 | R42: =R43+Q42 -> 1303382.1 | S42: =R42/N42 -> 16.364816 | T42: =S42-K42 -> 0.21481645
B43: 75 | C43: 5 | D43: ='Defunciones generales'!D94 -> 1550 | E43: =Homicidios!D1214 -> 2 | F43: =(D43-E43)/D43 -> 0.99870968 | G43: =LT!H75 -> 99647.622 | H43: =1-LT!G75 -> 0.831262 | I43: =1-H43 -> 0.168738 | J43: =LT!E94 -> 2.5 | K43: =LT!L75 -> 12.25 | L43: =H43^F43 -> 0.83146025 | M43: =1-L43 -> 0.16853975 | N43: =N42*L42 -> 71214.628 | O43: =N43*M43 -> 12002.496 | P43: =(((-5/24)*O42)+((2.5)*O43)+((5/24)*O44))/O43 -> 2.6239888 | Q43: =(C43*N44)+(P43*O43) -> 327555.08 | R43: =R44+Q43 -> 924995.26 | S43: =R43/N43 -> 12.988838 | T43: =S43-K43 -> 0.73883787
B44: 80 | C44: 5 | D44: ='Defunciones generales'!D95 -> 1835 | E44: =Homicidios!D1215 -> 1 | F44: =(D44-E44)/D44 -> 0.99945504 | G44: =LT!H76 -> 99646.626 | H44: =1-LT!G76 -> 0.736857 | I44: =1-H44 -> 0.263143 | J44: =LT!E95 -> 2.5 | K44: =LT!L76 -> 10.01 | L44: =H44^F44 -> 0.73697963 | M44: =1-L44 -> 0.26302037 | N44: =N43*L43 -> 59212.133 | O44: =N44*M44 -> 15573.997 | P44: =C44+(F44*(I44/M44)*(J44-C44)) -> 2.5001974 | Q44: =(C44*N45)+(P44*O44) -> 257128.75 | R44: =R45+Q44 -> 597440.18 | S44: =R44/N44 -> 10.089827 | T44: =S44-K44 -> 0.07982714
...

Sheet LT
A1: year | B1: sex | C1: age | D1: deaths | E1: ax | F1: mx | G1: qx | H1: lx | I1: dx | J1: Lx | K1: Tx | L1: ex
A2: 2010 | B2: male | C2: 0 | D2: 1.3333333 | E2: 0.09 | F2: 1.3333333e-05 | G2: 1.3333244e-05 | H2: 100000 | I2: 1.3333244 | J2: 99999.333 | K2: 1895252.4 | L2: =K2/H2 -> 18.952524
A3: 2010 | B3: male | C3: 1 | D3: 0.66666667 | E3: 1.61 | F3: 6.6666667e-06 | G3: 6.6666444e-06 | H3: 99998.667 | I3: 0.66665556 | J3: 99998.333 | K3: 1795253.1 | L3: 17.95277
A4: 2010 | B4: male | C4: 5 | D4: 0.66666667 | E4: 2.5 | F4: 6.6666667e-06 | G4: 6.6666444e-06 | H4: 99998 | I4: 0.66665111 | J4: 99997.667 | K4: 1695254.7 | L4: 16.952886
A5: 2010 | B5: male | C5: 10 | D5: 4 | E5: 2.5 | F5: 4e-05 | G5: 3.99992e-05 | H5: 99997.333 | I5: 3.9998133 | J5: 99995.333 | K5: 1595257.1 | L5: 15.952996
A6: 2010 | B6: male | C6: 15 | D6: 49.666667 | E6: 2.5 | F6: 0.00049666667 | G6: 0.00049654335 | H6: 99993.334 | I6: 49.651025 | J6: 99968.508 | K6: 1495261.7 | L6: 14.953614
A7: 2010 | B7: male | C7: 20 | D7: 67 | E7: 2.5 | F7: 0.00067 | G7: 0.0006697756 | H7: 99943.683 | I7: 66.93984 | J7: 99910.213 | K7: 1395293.2 | L7: 13.960795
A8: 2010 | B8: male | C8: 25 | D8: 71 | E8: 2.5 | F8: 0.00071 | G8: 0.00070974801 | H8: 99876.743 | I8: 70.887319 | J8: 99841.299 | K8: 1295383 | L8: 12.969816
A9: 2010 | B9: male | C9: 30 | D9: 67.666667 | E9: 2.5 | F9: 0.00067666667 | G9: 0.00067643778 | H9: 99805.855 | I9: 67.512451 | J9: 99772.099 | K9: 1195541.7 | L9: 11.978673
A10: 2010 | B10: male | C10: 35 | D10: 47 | E10: 2.5 | F10: 0.00047 | G10: 0.00046988957 | H10: 99738.343 | I10: 46.866007 | J10: 99714.91 | K10: 1095769.6 | L10: 10.986443
A11: 2010 | B11: male | C11: 40 | D11: 31.666667 | E11: 2.5 | F11: 0.00031666667 | G11: 0.00031661653 | H11: 99691.477 | I11: 31.56397 | J11: 99675.695 | K11: 996054.69 | L11: 9.9913726
A12: 2010 | B12: male | C12: 45 | D12: 23.666667 | E12: 2.5 | F12: 0.00023666667 | G12: 0.00023663866 | H12: 99659.913 | I12: 23.583389 | J12: 99648.121 | K12: 896379 | L12: 8.9943787
A13: 2010 | B13: male | C13: 50 | D13: 21.333333 | E13: 2.5 | F13: 0.00021333333 | G13: 0.00021331058 | H13: 99636.33 | I13: 21.253483 | J13: 99625.703 | K13: 796730.88 | L13: 7.9963893
A14: 2010 | B14: male | C14: 55 | D14: 12.666667 | E14: 2.5 | F14: 0.00012666667 | G14: 0.00012665864 | H14: 99615.076 | I14: 12.617111 | J14: 99608.768 | K14: 697105.17 | L14: 6.9979887
... A19: 2010 | B19: male | C19: 80 | D19: 2.3333333 | E19: 2.5 | F19: 2.3333333e-05 | G19: 2.3333061e-05 | H19: 99576.566 | I19: 2.3234261 | J19: 99575.404 | K19: 199148.65 | L19: 1.999955
A20: 2010 | B20: male | C20: 85 | D20: 2 | E20: NA | F20: 2e-05 | G20: 1.99998e-05 | H20: 99574.242 | I20: 1.9914649 | J20: 99573.247 | K20: 99573.247 | L20: 0.99999
A21: 2010 | B21: female | C21: 0 | D21: 1.3333333 | E21: 0.08 | F21: 1.3333333e-05 | G21: 1.3333244e-05 | H21: 100000 | I21: 1.3333244 | J21: 99999.333 | K21: 1899492.1 | L21: 18.994921
A22: 2010 | B22: female | C22: 1 | D22: 1.3333333 | E22: 1.61 | F22: 1.3333333e-05 | G22: 1.3333244e-05 | H22: 99998.667 | I22: 1.3333067 | J22: 99998 | K22: 1799492.8 | L22: 17.995168
A23: 2010 | B23: female | C23: 5 | D23: 1.6666667 | E23: 2.5 | F23: 1.6666667e-05 | G23: 1.6666528e-05 | H23: 99997.333 | I23: 1.6666083 | J23: 99996.5 | K23: 1699494.8 | L23: 16.995401
A24: 2010 | B24: female | C24: 10 | D24: 1.3333333 | E24: 2.5 | F24: 1.3333333e-05 | G24: 1.3333244e-05 | H24: 99995.667 | I24: 1.3332667 | J24: 99995 | K24: 1599498.3 | L24: 15.995676
A25: 2010 | B25: female | C25: 15 | D25: 1.6666667 | E25: 2.5 | F25: 1.6666667e-05 | G25: 1.6666528e-05 | H25: 99994.333 | I25: 1.6665583 | J25: 99993.5 | K25: 1499503.3 | L25: 14.995882
A26: 2010 | B26: female | C26: 20 | D26: 7.3333333 | E26: 2.5 | F26: 7.3333333e-05 | G26: 7.3330645e-05 | H26: 99992.667 | I26: 7.3325267 | J26: 99989.001 | K26: 1399509.8 | L26: 13.996124
A27: 2010 | B27: female | C27: 25 | D27: 6.3333333 | E27: 2.5 | F27: 6.3333333e-05 | G27: 6.3331328e-05 | H27: 99985.334 | I27: 6.332204 | J27: 99982.168 | K27: 1299520.8 | L27: 12.997114
A28: 2010 | B28: female | C28: 30 | D28: 4.6666667 | E28: 2.5 | F28: 4.6666667e-05 | G28: 4.6665578e-05 | H28: 99979.002 | I28: 4.6655779 | J28: 99976.669 | K28: 1199538.6 | L28: 11.997905
A29: 2010 | B29: female | C29: 35 | D29: 5.3333333 | E29: 2.5 | F29: 5.3333333e-05 | G29: 5.3331911e-05 | H29: 99974.337 | I29: 5.3318224 | J29: 99971.671 | K29: 1099561.9 | L29: 10.998442
A30: 2010 | B30: female | C30: 40 | D30: 2.3333333 | E30: 2.5 | F30: 2.3333333e-05 | G30: 2.3333061e-05 | H30: 99969.005 | I30: 2.3325829 | J30: 99967.839 | K30: 999590.25 | L30: 9.9990017
A31: 2010 | B31: female | C31: 45 | D31: 1.6666667 | E31: 2.5 | F31: 1.6666667e-05 | G31: 1.6666528e-05 | H31: 99966.672 | I31: 1.6660973 | J31: 99965.839 | K31: 899622.41 | L31: 8.9992234
A32: 2010 | B32: female | C32: 50 | D32: 2.6666667 | E32: 2.5 | F32: 2.6666667e-05 | G32: 2.6666311e-05 | H32: 99965.006 | I32: 2.665698 | J32: 99963.673 | K32: 799656.57 | L32: 7.999365
... A38: 2010 | B38: female | C38: 80 | D38: 1 | E38: 2.5 | F38: 1e-05 | G38: 9.99995e-06 | H38: 99953.344 | I38: 0.99952844 | J38: 99952.844 | K38: 199905.02 | L38: 1.9999833
A39: 2010 | B39: female | C39: 85 | D39: 0.33333333 | E39: NA | F39: 3.3333333e-06 | G39: 3.3333278e-06 | H39: 99952.345 | I39: 0.33317393 | J39: 99952.178 | K39: 99952.178 | L39: 0.99999833
A40: 2019 | B40: male | C40: 0 | D40: 2.5 | E40: 0.08 | F40: 2.5e-05 | G40: 0.013946 | H40: 100000 | I40: 2.4999688 | J40: 99998.75 | K40: 1865003.2 | L40: 72.41
A41: 2019 | B41: male | C41: 1 | D41: 4.5 | E41: 1.62 | F41: 4.5e-05 | G41: 0.002404 | H41: 99997.5 | I41: 4.4997863 | J41: 99995.25 | K41: 1765004.4 | L41: 71.01
A42: 2019 | B42: male | C42: 5 | D42: 5 | E42: 2.5 | F42: 5e-05 | G42: 0.001234 | H42: 99993 | I42: 4.999525 | J42: 99990.5 | K42: 1665009.2 | L42: 67.54
A43: 2019 | B43: male | C43: 10 | D43: 20 | E43: 2.5 | F43: 0.0002 | G43: 0.001685 | H43: 99988.001 | I43: 19.995601 | J43: 99978.003 | K43: 1565018.7 | L43: 61.38
A44: 2019 | B44: male | C44: 15 | D44: 264 | E44: 2.5 | F44: 0.00264 | G44: 0.006142 | H44: 99968.005 | I44: 263.56747 | J44: 99836.221 | K44: 1465040.7 | L44: 59.35
A45: 2019 | B45: male | C45: 20 | D45: 532.5 | E45: 2.5 | F45: 0.005325 | G45: 0.011511 | H45: 99704.438 | I45: 529.51505 | J45: 99439.68 | K45: 1365204.5 | L45: 54.71
A46: 2019 | B46: male | C46: 25 | D46: 587.5 | E46: 2.5 | F46: 0.005875 | G46: 0.01444 | H46: 99174.923 | I46: 580.94447 | J46: 98884.45 | K46: 1265764.8 | L46: 49.68
A47: 2019 | B47: male | C47: 30 | D47: 512.5 | E47: 2.5 | F47: 0.005125 | G47: 0.01549 | H47: 98593.978 | I47: 504.00153 | J47: 98341.977 | K47: 1166880.3 | L47: 45.09
A48: 2019 | B48: male | C48: 35 | D48: 406 | E48: 2.5 | F48: 0.00406 | G48: 0.01766 | H48: 98089.977 | I48: 397.43796 | J48: 97891.258 | K48: 1068538.4 | L48: 40.28
A49: 2019 | B49: male | C49: 40 | D49: 308.5 | E49: 2.5 | F49: 0.003085 | G49: 0.022155 | H49: 97692.539 | I49: 300.91708 | J49: 97542.08 | K49: 970647.1 | L49: 36.09
...

Sheet Homicidios
A1: year | B1: age | C1: sex | D1: deaths
A2: 1990 | B2: 0 | C2: male | D2: 1
A3: 1990 | B3: 1 | C3: male | D3: 2
A4: 1990 | B4: 5 | C4: male | D4: 4
A5: 1990 | B5: 10 | C5: male | D5: 5
A6: 1990 | B6: 15 | C6: male | D6: 41
A7: 1990 | B7: 20 | C7: male | D7: 67
A8: 1990 | B8: 25 | C8: male | D8: 43.895833
A9: 1990 | B9: 30 | C9: male | D9: 32
A10: 1990 | B10: 35 | C10: male | D10: 32
A11: 1990 | B11: 40 | C11: male | D11: 23
A12: 1990 | B12: 45 | C12: male | D12: 18
A13: 1990 | B13: 50 | C13: male | D13: 28
... A1311: 2024 | B1311: 85 | C1311: female | D1311: 0

Sheet Defunciones generales
A1: year | B1: sex | C1: age | D1: deaths
A2: 2010 | B2: male | C2: 0 | D2: 863.98194
A3: 2010 | B3: male | C3: 1 | D3: 135.52248
A4: 2010 | B4: male | C4: 5 | D4: 77.298007
A5: 2010 | B5: male | C5: 10 | D5: 124.47991
A6: 2010 | B6: male | C6: 15 | D6: 332.28104
A7: 2010 | B7: male | C7: 20 | D7: 395.52487
A8: 2010 | B8: male | C8: 25 | D8: 373.43972
A9: 2010 | B9: male | C9: 30 | D9: 370.42811
A10: 2010 | B10: male | C10: 35 | D10: 472.82288
A11: 2010 | B11: male | C11: 40 | D11: 521.00865
A12: 2010 | B12: male | C12: 45 | D12: 577.22538
A13: 2010 | B13: male | C13: 50 | D13: 738.84849
... A115: 2021 | B115: female | C115: 85 | D115: 5402.2282
